<?xml version="1.0" ?>
<!-- =================================================================================== -->
<!-- |    This document was autogenerated by xacro from rv_4frl_d.xacro                | -->
<!-- |    EDITING THIS FILE BY HAND IS NOT RECOMMENDED                                 | -->
<!-- =================================================================================== -->
<robot name="rv_4frl_d">
  <!-- Used for fixing robot -->
  <link name="world"/>
  <gazebo reference="world">
    <static>true</static>
  </gazebo>
  <material name="housing">
    <color rgba="0.79216 0.81961 0.93333 1"/>
  </material>
  <link name="rv_4frl_d_base_link">
    <inertial>
      <mass value="1"/>
      <inertia ixx="1.0" ixy="0.0" ixz="0.0" iyy="1.0" iyz="0.0" izz="1.0"/>
    </inertial>
    <visual>
      <origin rpy="1.5707963267948966 0 3.141592653589793" xyz="0 0 0"/>
      <geometry>
        <mesh filename="file:///root/ros2_ws/install/mitsubishi_ros2_description/share/mitsubishi_ros2_description/meshes/rv_4frl_d/RV-4FRL_01_BASE.stl" scale="0.001 0.001 0.001"/>
      </geometry>
      <material name="housing"/>
    </visual>
    <collision>
      <origin rpy="1.5707963267948966 0.00000000 3.141592653589793" xyz="0 0 0"/>
      <geometry>
        <mesh filename="file:///root/ros2_ws/install/mitsubishi_ros2_description/share/mitsubishi_ros2_description/meshes/rv_4frl_d/RV-4FRL_01_BASE.stl" scale="0.001 0.001 0.001"/>
      </geometry>
    </collision>
  </link>
  <joint name="rv_4frl_d_base" type="fixed">
    <origin rpy="0 0 0" xyz="0 0 0"/>
    <parent link="world"/>
    <child link="rv_4frl_d_base_link"/>
  </joint>
  <joint name="J1" type="revolute">
    <origin rpy="0 0 0" xyz="0 0 0"/>
    <parent link="rv_4frl_d_base_link"/>
    <child link="link_1"/>
    <axis xyz="0 0 1"/>
    <limit acceleration="17453.29251994" effort="32.21000000" jerk="17.45329252" lower="-4.1887902047863905" upper="4.1887902047863905" velocity="7.3303828583761845"/>
  </joint>
  <link name="link_1">
    <inertial>
      <mass value="1"/>
      <inertia ixx="1.0" ixy="0.0" ixz="0.0" iyy="1.0" iyz="0.0" izz="1.0"/>
    </inertial>
    <visual>
      <origin rpy="1.5707963267948966 0.0 0.0" xyz="0 0 0"/>
      <geometry>
        <mesh filename="file:///root/ros2_ws/install/mitsubishi_ros2_description/share/mitsubishi_ros2_description/meshes/rv_4frl_d/RV-4FRL_02_SHOULDER.stl" scale="0.001 0.001 0.001"/>
      </geometry>
      <material name="housing"/>
    </visual>
    <collision>
      <origin rpy="1.5707963267948966 0.0 0.0" xyz="0 0 0"/>
      <geometry>
        <mesh filename="file:///root/ros2_ws/install/mitsubishi_ros2_description/share/mitsubishi_ros2_description/meshes/rv_4frl_d/RV-4FRL_02_SHOULDER.stl" scale="0.001 0.001 0.001"/>
      </geometry>
    </collision>
  </link>
  <joint name="J2" type="revolute">
    <origin rpy="1.5707963267948966 0 3.141592653589793" xyz="0 0 0.350"/>
    <parent link="link_1"/>
    <child link="link_2"/>
    <axis xyz="0 0 1"/>
    <limit acceleration="17453.29251994" effort="32.21000000" jerk="17.45329252" lower="-2.0943951023931953" upper="2.0943951023931953" velocity="5.8643062867009474"/>
  </joint>
  <link name="link_2">
    <inertial>
      <mass value="1"/>
      <inertia ixx="1.0" ixy="0.0" ixz="0.0" iyy="1.0" iyz="0.0" izz="1.0"/>
    </inertial>
    <visual>
      <origin rpy="0.0 0.0 0.0" xyz="0 -0.350 0 "/>
      <geometry>
        <mesh filename="file:///root/ros2_ws/install/mitsubishi_ros2_description/share/mitsubishi_ros2_description/meshes/rv_4frl_d/RV-4FRL_03_NO1ARM.stl" scale="0.001 0.001 0.001"/>
      </geometry>
      <material name="housing"/>
    </visual>
    <collision>
      <origin rpy="0.0 0.0 0.0" xyz="0 -0.350 0 "/>
      <geometry>
        <mesh filename="file:///root/ros2_ws/install/mitsubishi_ros2_description/share/mitsubishi_ros2_description/meshes/rv_4frl_d/RV-4FRL_03_NO1ARM.stl" scale="0.001 0.001 0.001"/>
      </geometry>
    </collision>
  </link>
  <joint name="J3" type="revolute">
    <origin rpy="0.0 0.0 0.0" xyz="0 0.310 0"/>
    <parent link="link_2"/>
    <child link="link_3"/>
    <axis xyz="0 0 1"/>
    <limit acceleration="17453.29251994" effort="32.21000000" jerk="17.45329252" lower="0.0" upper="2.8623399732707" velocity="4.363323129985823"/>
  </joint>
  <link name="link_3">
    <inertial>
      <mass value="1"/>
      <inertia ixx="1.0" ixy="0.0" ixz="0.0" iyy="1.0" iyz="0.0" izz="1.0"/>
    </inertial>
    <visual>
      <origin rpy="0 0 0" xyz="0 -0.6599999999999999 0"/>
      <geometry>
        <mesh filename="file:///root/ros2_ws/install/mitsubishi_ros2_description/share/mitsubishi_ros2_description/meshes/rv_4frl_d/RV-4FRL_04_ELBOW.stl" scale="0.001 0.001 0.001"/>
      </geometry>
      <material name="housing"/>
    </visual>
    <collision>
      <origin rpy="0 0 0" xyz="0 -0.6599999999999999 0"/>
      <geometry>
        <mesh filename="file:///root/ros2_ws/install/mitsubishi_ros2_description/share/mitsubishi_ros2_description/meshes/rv_4frl_d/RV-4FRL_04_ELBOW.stl" scale="0.001 0.001 0.001"/>
      </geometry>
    </collision>
  </link>
  <joint name="J4" type="revolute">
    <origin rpy="1.5707963267948966 0.00000000 0.00000000" xyz="0.0 0.050 0.0"/>
    <parent link="link_3"/>
    <child link="link_4"/>
    <axis xyz="1 0 0"/>
    <limit acceleration="17453.29251994" effort="32.21000000" jerk="17.45329252" lower="-3.490658503988659" upper="3.490658503988659" velocity="9.42477796076938"/>
  </joint>
  <link name="link_4">
    <inertial>
      <mass value="1"/>
      <inertia ixx="1.0" ixy="0.0" ixz="0.0" iyy="1.0" iyz="0.0" izz="1.0"/>
    </inertial>
    <visual>
      <origin rpy="1.5707963267948966 0 0" xyz="0 0 -0.71"/>
      <geometry>
        <mesh filename="file:///root/ros2_ws/install/mitsubishi_ros2_description/share/mitsubishi_ros2_description/meshes/rv_4frl_d/RV-4FRL_05_NO2ARM.stl" scale="0.001 0.001 0.001"/>
      </geometry>
      <material name="housing"/>
    </visual>
    <collision>
      <origin rpy="1.57079633 0 0" xyz="-0.0498 0 -0.525"/>
      <geometry>
        <mesh filename="file:///root/ros2_ws/install/mitsubishi_ros2_description/share/mitsubishi_ros2_description/meshes/rv_4frl_d/RV-4FRL_05_NO2ARM.stl" scale="0.001 0.001 0.001"/>
      </geometry>
    </collision>
  </link>
  <joint name="J5" type="revolute">
    <origin rpy="1.5707963267948966 0.00000000 0.00000000" xyz="-0.335 0.0 0.0"/>
    <parent link="link_4"/>
    <child link="link_5"/>
    <axis xyz="0 0 1"/>
    <limit acceleration="17453.29251994" effort="32.21000000" jerk="17.45329252" lower="-2.0943951023931953" upper="2.0943951023931953" velocity="10.873401239924673"/>
  </joint>
  <link name="link_5">
    <inertial>
      <mass value="1"/>
      <inertia ixx="1.0" ixy="0.0" ixz="0.0" iyy="1.0" iyz="0.0" izz="1.0"/>
    </inertial>
    <visual>
      <origin rpy="0 0 0" xyz="0.335 -0.71 0.0 "/>
      <geometry>
        <mesh filename="file:///root/ros2_ws/install/mitsubishi_ros2_description/share/mitsubishi_ros2_description/meshes/rv_4frl_d/RV-4FRL_06_WRIST.stl" scale="0.001 0.001 0.001"/>
      </geometry>
      <material name="housing"/>
    </visual>
    <collision>
      <origin rpy="0 0 0" xyz="-0.0498 -0.795 0"/>
      <geometry>
        <mesh filename="file:///root/ros2_ws/install/mitsubishi_ros2_description/share/mitsubishi_ros2_description/meshes/rv_4frl_d/RV-4FRL_06_WRIST.stl" scale="0.001 0.001 0.001"/>
      </geometry>
    </collision>
  </link>
  <joint name="J6" type="revolute">
    <origin rpy="3.141592653589793 0.0 0.0" xyz="-0.08 0.0 0.0"/>
    <parent link="link_5"/>
    <child link="link_6"/>
    <axis xyz="1 0 0"/>
    <limit acceleration="17453.29251994" effort="32.21000000" jerk="17.45329252" lower="-6.283185307179586" upper="6.283185307179586" velocity="12.566370614359172"/>
  </joint>
  <link name="link_6">
    <inertial>
      <mass value="1"/>
      <inertia ixx="1.0" ixy="0.0" ixz="0.0" iyy="1.0" iyz="0.0" izz="1.0"/>
    </inertial>
    <visual>
      <origin rpy="0 0 0" xyz="0.41500000000000004 -0.71 0"/>
      <geometry>
        <mesh filename="file:///root/ros2_ws/install/mitsubishi_ros2_description/share/mitsubishi_ros2_description/meshes/rv_4frl_d/RV-4FRL_07_HAND_FLANGE.stl" scale="0.001 0.001 0.001"/>
      </geometry>
      <material name="housing"/>
    </visual>
    <collision>
      <origin rpy="1.5 0 0" xyz="-0.05 -0.05 -0.795"/>
      <geometry>
        <mesh filename="file:///root/ros2_ws/install/mitsubishi_ros2_description/share/mitsubishi_ros2_description/meshes/rv_4frl_d/RV-4FRL_07_HAND_FLANGE.stl" scale="0.001 0.001 0.001"/>
      </geometry>
    </collision>
  </link>
  <link name="tool0">
    <inertial>
      <mass value="1"/>
      <inertia ixx="1.0" ixy="0.0" ixz="0.0" iyy="1.0" iyz="0.0" izz="1.0"/>
    </inertial>
  </link>
  <joint name="J6-tool0" type="fixed">
    <origin rpy="0 0 0" xyz="0 0 0"/>
    <parent link="link_6"/>
    <child link="tool0"/>
  </joint>
</robot>
