<?xml version="1.0" encoding="utf-8"?>
<robot xmlns:xacro="http://www.ros.org/wiki/xacro">

  <xacro:macro name="rv_2frb_d" params="parent prefix *origin">
    
    <material name="housing">
      <color rgba="0.79216 0.81961 0.93333 1"/>
    </material>

    <link name="${prefix}rv_2frb_d_base_link">
      <inertial>
            <mass value="1"/>
            <inertia ixx="1.0" ixy="0.0" ixz="0.0" iyy="1.0" iyz="0.0" izz="1.0"/>
      </inertial>
      <visual>
        <origin xyz="0 0 0" rpy="1.57079633 0.00000000 3.14159265" />
        <geometry>
          <mesh filename="file://$(find mitsubishi_ros2_description)/meshes/rv_2frb_d/RV-2FR_01_base.stl"/>          
        </geometry>
        <material name="housing"/>
      </visual>
      <collision>
        <origin xyz="0 0 0" rpy="1.57079633 0.00000000 3.14159265" />
        <geometry>
          <mesh filename="file://$(find mitsubishi_ros2_description)/meshes/rv_2frb_d/RV-2FR_01_base.stl"/>           
        </geometry>
      </collision>
    </link>   
    
    <link name="${prefix}link_1">
      <inertial>
          <mass value="1"/>
          <inertia ixx="1.0" ixy="0.0" ixz="0.0" iyy="1.0" iyz="0.0" izz="1.0"/>
      </inertial>
      <visual>
        <origin xyz="0 0 0" rpy="1.57079633 0.00000000 0.00000000" />
        <geometry>          
          <mesh filename="file://$(find mitsubishi_ros2_description)/meshes/rv_2frb_d/RV-2FR_02_link1_Shoulder.stl" />
        </geometry>
        <material name="housing"/>
      </visual>
      <collision>
        <origin xyz="0 0 0" rpy="1.57079633 0.00000000 0.00000000" />
        <geometry>
          <mesh filename="file://$(find mitsubishi_ros2_description)/meshes/rv_2frb_d/RV-2FR_02_link1_Shoulder.stl" />
        </geometry>
      </collision>
    </link>      

    <link name="${prefix}link_2">
      <inertial>
        <mass value="1"/>
        <inertia ixx="1.0" ixy="0.0" ixz="0.0" iyy="1.0" iyz="0.0" izz="1.0"/>
      </inertial>
      <visual>
        <origin xyz="0 -0.295 0" rpy="0.00000000 0.00000000 0.00000000" />
        <geometry>
          <mesh filename="file://$(find mitsubishi_ros2_description)/meshes/rv_2frb_d/RV-2FR_03_link2_No1Arm.stl" />
        </geometry>
        <material name="housing"/>
      </visual>
      <collision>
        <origin xyz="0 -0.295 0" rpy="0 0 0" />
        <geometry>
          <mesh filename="file://$(find mitsubishi_ros2_description)/meshes/rv_2frb_d/RV-2FR_03_link2_No1Arm.stl" />
        </geometry>
      </collision>
    </link>
    
    <link name="${prefix}link_3">
      <inertial>
        <mass value="1"/>
        <inertia ixx="1.0" ixy="0.0" ixz="0.0" iyy="1.0" iyz="0.0" izz="1.0"/>
      </inertial>
      <visual>
        <origin xyz="0 0 0" rpy="0.00000000 1.57079633 3.14159265" />
        <geometry>
          <mesh filename="file://$(find mitsubishi_ros2_description)/meshes/rv_2frb_d/RV-2FR_04_link3_Elbow.stl" />
        </geometry>
        <material name="housing"/>
      </visual>
      <collision>
        <origin xyz="0 0 0" rpy="0.00000000 1.57079633 3.14159265" />
        <geometry>
          <mesh filename="file://$(find mitsubishi_ros2_description)/meshes/rv_2frb_d/RV-2FR_04_link3_Elbow.stl" />
        </geometry>
      </collision>
    </link>
    
    <link name="${prefix}link_4">
      <inertial>
        <mass value="1"/>
        <inertia ixx="1.0" ixy="0.0" ixz="0.0" iyy="1.0" iyz="0.0" izz="1.0"/>
      </inertial>
      <visual>
        <origin xyz="-0.575 0 0" rpy="0 1.57079633 -1.57079633" />
        <geometry>
          <mesh filename="file://$(find mitsubishi_ros2_description)/meshes/rv_2frb_d/RV-2FR_05_link4_No2Arm.stl" />
        </geometry>
        <material name="housing"/>
      </visual>
      <collision>
        <origin xyz="-0.575 0 0" rpy="0 1.57079633 -1.57079633" />
        <geometry>
          <mesh filename="file://$(find mitsubishi_ros2_description)/meshes/rv_2frb_d/RV-2FR_05_link4_No2Arm.stl" />
        </geometry>
      </collision>
    </link>

    <link name="${prefix}link_5">
      <inertial>
        <mass value="1"/>
        <inertia ixx="1.0" ixy="0.0" ixz="0.0" iyy="1.0" iyz="0.0" izz="1.0"/>
      </inertial>
      <visual>
        <origin xyz="-0.575 -0.27 0" rpy="0 0 -1.57079633" />
        <geometry>
          <mesh filename="file://$(find mitsubishi_ros2_description)/meshes/rv_2frb_d/RV-2FR_06_link5_Wrist.stl" />
        </geometry>
        <material name="housing"/>
      </visual>
      <collision>
        <origin xyz="-0.575 -0.27 0" rpy="0 0 -1.57079633" />
        <geometry>
          <mesh filename="file://$(find mitsubishi_ros2_description)/meshes/rv_2frb_d/RV-2FR_06_link5_Wrist.stl" />
        </geometry>
      </collision>
    </link>

    <link name="${prefix}link_6">
      <inertial>
        <mass value="1"/>
        <inertia ixx="1.0" ixy="0.0" ixz="0.0" iyy="1.0" iyz="0.0" izz="1.0"/>
      </inertial>
      <visual>
        <origin xyz="0.575 0 -0.270" rpy="0 1.57079633 1.57079633" />
        <geometry>
          <mesh filename="file://$(find mitsubishi_ros2_description)/meshes/rv_2frb_d/RV-2FR_07_link6_Flange.stl" />
        </geometry>
        <material name="housing"/>
      </visual>
      <collision>
        <origin xyz="0.575 0 -0.270" rpy="0 1.57079633 1.57079633" />
        <geometry>
          <mesh filename="file://$(find mitsubishi_ros2_description)/meshes/rv_2frb_d/RV-2FR_07_link6_Flange.stl" />
        </geometry>
      </collision>
    </link>

    <link name="${prefix}tool0">
      <inertial>
        <mass value="1"/>
        <inertia ixx="1.0" ixy="0.0" ixz="0.0" iyy="1.0" iyz="0.0" izz="1.0"/>
      </inertial>
    </link>

    <joint name="${prefix}rv_2frb_d_base" type="fixed">
        <xacro:insert_block name="origin" />
        <parent link="${parent}"/>
        <child link="${prefix}rv_2frb_d_base_link"/>
    </joint>

    <joint name="${prefix}J1" type="revolute">
      <origin xyz="0 0 0" rpy="0 0 0" />
      <parent link="${prefix}rv_2frb_d_base_link" />
      <child link="${prefix}link_1" />
      <axis xyz="0 0 1" />
      <limit
        lower="-4.1887902" upper="4.1887902"
        velocity="1.57079633"
        acceleration="17453.29251994"
        jerk="17.45329252"
        effort="32.21000000" />
    </joint>
    
    <joint name="${prefix}J2" type="revolute">
      <origin xyz="0 0 0.295" rpy="1.57079633 0 3.14159265" />
      <parent link="${prefix}link_1" />
      <child link="${prefix}link_2" />
      <axis xyz="0 0 1" />
      <limit
        lower="-2.0943951" upper="2.0943951"
        velocity="1.57079633"
        acceleration="17453.29251994"
        jerk="17.45329252"
        effort="32.21000000" />
    </joint>
    
    <joint name="${prefix}J3" type="revolute">
      <origin xyz="0.000 0.230 0.000" rpy="0.00000000 0.00000000 0.00000000" />
      <parent link="${prefix}link_2" />
      <child link="${prefix}link_3" />
      <axis xyz="0 0 1" />
      <limit
        lower="0" upper="2.7925268"
        velocity="1.57079633"
        acceleration="17453.29251994"
        jerk="17.45329252"
        effort="32.21000000" />
    </joint>
    
    <joint name="${prefix}J4" type="revolute">
      <origin xyz="0.050 0.000 0.000" rpy="-1.57079633 0.00000000 0.00000000" />
      <parent link="${prefix}link_3" />
      <child link="${prefix}link_4" />
      <axis xyz="0 0 1" />
      <limit
        lower="-3.4906585" upper="3.4906585"
        velocity="1.57079633"
        acceleration="17453.29251994"
        jerk="17.45329252"
        effort="32.21000000" />
    </joint>
    
    <joint name="${prefix}J5" type="revolute">
      <origin xyz="0.000 0.000 0.270" rpy="1.57079633 0.00000000 0.00000000" />
      <parent link="${prefix}link_4" />
      <child link="${prefix}link_5" />
      <axis xyz="0 0 1" />
      <limit
        lower="-2.0943951" upper="2.0943951"
        velocity="1.57079633"
        acceleration="17453.29251994"
        jerk="17.45329252"
        effort="32.21000000" />
    </joint>
    
    <joint name="${prefix}J6" type="revolute">
      <origin xyz="0.000 0.000 0.000" rpy="-1.57079633 0.00000000 0.00000000" />
      <parent link="${prefix}link_5" />
      <child link="${prefix}link_6" />
      <axis xyz="0 0 1" />
      <limit
        lower="-6.28318531" upper="6.28318531"
        velocity="1.57079633"
        acceleration="17453.29251994"
        jerk="17.45329252"
        effort="32.21000000" />
    </joint>

    <joint name="${prefix}J6-tool0" type="fixed">
        <origin rpy="0 0 0" xyz="0 0 0"/>
        <parent link="${prefix}link_6"/>
        <child link="${prefix}tool0"/>
    </joint>

  </xacro:macro>
</robot>
