<?xml version="1.0" ?>
<!-- =================================================================================== -->
<!-- |    This document was autogenerated by xacro from rv_2frb_d.xacro                | -->
<!-- |    EDITING THIS FILE BY HAND IS NOT RECOMMENDED                                 | -->
<!-- =================================================================================== -->
<robot name="rv_2frb_d">
  <!-- Used for fixing robot -->
  <link name="world"/>
  <gazebo reference="world">
    <static>true</static>
  </gazebo>
  <material name="housing">
    <color rgba="0.79216 0.81961 0.93333 1"/>
  </material>
  <link name="rv_2frb_d_base_link">
    <inertial>
      <mass value="1"/>
      <inertia ixx="1.0" ixy="0.0" ixz="0.0" iyy="1.0" iyz="0.0" izz="1.0"/>
    </inertial>
    <visual>
      <origin rpy="1.57079633 0.00000000 3.14159265" xyz="0 0 0"/>
      <geometry>
        <mesh filename="file:///root/ros2_ws/install/mitsubishi_ros2_description/share/mitsubishi_ros2_description/meshes/rv_2frb_d/RV-2FR_01_base.stl"/>
      </geometry>
      <material name="housing"/>
    </visual>
    <collision>
      <origin rpy="1.57079633 0.00000000 3.14159265" xyz="0 0 0"/>
      <geometry>
        <mesh filename="file:///root/ros2_ws/install/mitsubishi_ros2_description/share/mitsubishi_ros2_description/meshes/rv_2frb_d/RV-2FR_01_base.stl"/>
      </geometry>
    </collision>
  </link>
  <link name="link_1">
    <inertial>
      <mass value="1"/>
      <inertia ixx="1.0" ixy="0.0" ixz="0.0" iyy="1.0" iyz="0.0" izz="1.0"/>
    </inertial>
    <visual>
      <origin rpy="1.57079633 0.00000000 0.00000000" xyz="0 0 0"/>
      <geometry>
        <mesh filename="file:///root/ros2_ws/install/mitsubishi_ros2_description/share/mitsubishi_ros2_description/meshes/rv_2frb_d/RV-2FR_02_link1_Shoulder.stl"/>
      </geometry>
      <material name="housing"/>
    </visual>
    <collision>
      <origin rpy="1.57079633 0.00000000 0.00000000" xyz="0 0 0"/>
      <geometry>
        <mesh filename="file:///root/ros2_ws/install/mitsubishi_ros2_description/share/mitsubishi_ros2_description/meshes/rv_2frb_d/RV-2FR_02_link1_Shoulder.stl"/>
      </geometry>
    </collision>
  </link>
  <link name="link_2">
    <inertial>
      <mass value="1"/>
      <inertia ixx="1.0" ixy="0.0" ixz="0.0" iyy="1.0" iyz="0.0" izz="1.0"/>
    </inertial>
    <visual>
      <origin rpy="0.00000000 0.00000000 0.00000000" xyz="0 -0.295 0"/>
      <geometry>
        <mesh filename="file:///root/ros2_ws/install/mitsubishi_ros2_description/share/mitsubishi_ros2_description/meshes/rv_2frb_d/RV-2FR_03_link2_No1Arm.stl"/>
      </geometry>
      <material name="housing"/>
    </visual>
    <collision>
      <origin rpy="0 0 0" xyz="0 -0.295 0"/>
      <geometry>
        <mesh filename="file:///root/ros2_ws/install/mitsubishi_ros2_description/share/mitsubishi_ros2_description/meshes/rv_2frb_d/RV-2FR_03_link2_No1Arm.stl"/>
      </geometry>
    </collision>
  </link>
  <link name="link_3">
    <inertial>
      <mass value="1"/>
      <inertia ixx="1.0" ixy="0.0" ixz="0.0" iyy="1.0" iyz="0.0" izz="1.0"/>
    </inertial>
    <visual>
      <origin rpy="0.00000000 1.57079633 3.14159265" xyz="0 0 0"/>
      <geometry>
        <mesh filename="file:///root/ros2_ws/install/mitsubishi_ros2_description/share/mitsubishi_ros2_description/meshes/rv_2frb_d/RV-2FR_04_link3_Elbow.stl"/>
      </geometry>
      <material name="housing"/>
    </visual>
    <collision>
      <origin rpy="0.00000000 1.57079633 3.14159265" xyz="0 0 0"/>
      <geometry>
        <mesh filename="file:///root/ros2_ws/install/mitsubishi_ros2_description/share/mitsubishi_ros2_description/meshes/rv_2frb_d/RV-2FR_04_link3_Elbow.stl"/>
      </geometry>
    </collision>
  </link>
  <link name="link_4">
    <inertial>
      <mass value="1"/>
      <inertia ixx="1.0" ixy="0.0" ixz="0.0" iyy="1.0" iyz="0.0" izz="1.0"/>
    </inertial>
    <visual>
      <origin rpy="0 1.57079633 -1.57079633" xyz="-0.575 0 0"/>
      <geometry>
        <mesh filename="file:///root/ros2_ws/install/mitsubishi_ros2_description/share/mitsubishi_ros2_description/meshes/rv_2frb_d/RV-2FR_05_link4_No2Arm.stl"/>
      </geometry>
      <material name="housing"/>
    </visual>
    <collision>
      <origin rpy="0 1.57079633 -1.57079633" xyz="-0.575 0 0"/>
      <geometry>
        <mesh filename="file:///root/ros2_ws/install/mitsubishi_ros2_description/share/mitsubishi_ros2_description/meshes/rv_2frb_d/RV-2FR_05_link4_No2Arm.stl"/>
      </geometry>
    </collision>
  </link>
  <link name="link_5">
    <inertial>
      <mass value="1"/>
      <inertia ixx="1.0" ixy="0.0" ixz="0.0" iyy="1.0" iyz="0.0" izz="1.0"/>
    </inertial>
    <visual>
      <origin rpy="0 0 -1.57079633" xyz="-0.575 -0.27 0"/>
      <geometry>
        <mesh filename="file:///root/ros2_ws/install/mitsubishi_ros2_description/share/mitsubishi_ros2_description/meshes/rv_2frb_d/RV-2FR_06_link5_Wrist.stl"/>
      </geometry>
      <material name="housing"/>
    </visual>
    <collision>
      <origin rpy="0 0 -1.57079633" xyz="-0.575 -0.27 0"/>
      <geometry>
        <mesh filename="file:///root/ros2_ws/install/mitsubishi_ros2_description/share/mitsubishi_ros2_description/meshes/rv_2frb_d/RV-2FR_06_link5_Wrist.stl"/>
      </geometry>
    </collision>
  </link>
  <link name="link_6">
    <inertial>
      <mass value="1"/>
      <inertia ixx="1.0" ixy="0.0" ixz="0.0" iyy="1.0" iyz="0.0" izz="1.0"/>
    </inertial>
    <visual>
      <origin rpy="0 1.57079633 1.57079633" xyz="0.575 0 -0.270"/>
      <geometry>
        <mesh filename="file:///root/ros2_ws/install/mitsubishi_ros2_description/share/mitsubishi_ros2_description/meshes/rv_2frb_d/RV-2FR_07_link6_Flange.stl"/>
      </geometry>
      <material name="housing"/>
    </visual>
    <collision>
      <origin rpy="0 1.57079633 1.57079633" xyz="0.575 0 -0.270"/>
      <geometry>
        <mesh filename="file:///root/ros2_ws/install/mitsubishi_ros2_description/share/mitsubishi_ros2_description/meshes/rv_2frb_d/RV-2FR_07_link6_Flange.stl"/>
      </geometry>
    </collision>
  </link>
  <link name="tool0">
    <inertial>
      <mass value="1"/>
      <inertia ixx="1.0" ixy="0.0" ixz="0.0" iyy="1.0" iyz="0.0" izz="1.0"/>
    </inertial>
  </link>
  <joint name="rv_2frb_d_base" type="fixed">
    <origin rpy="0 0 0" xyz="0 0 0"/>
    <parent link="world"/>
    <child link="rv_2frb_d_base_link"/>
  </joint>
  <joint name="J1" type="revolute">
    <origin rpy="0 0 0" xyz="0 0 0"/>
    <parent link="rv_2frb_d_base_link"/>
    <child link="link_1"/>
    <axis xyz="0 0 1"/>
    <limit acceleration="17453.29251994" effort="32.21000000" jerk="17.45329252" lower="-4.1887902" upper="4.1887902" velocity="1.57079633"/>
  </joint>
  <joint name="J2" type="revolute">
    <origin rpy="1.57079633 0 3.14159265" xyz="0 0 0.295"/>
    <parent link="link_1"/>
    <child link="link_2"/>
    <axis xyz="0 0 1"/>
    <limit acceleration="17453.29251994" effort="32.21000000" jerk="17.45329252" lower="-2.0943951" upper="2.0943951" velocity="1.57079633"/>
  </joint>
  <joint name="J3" type="revolute">
    <origin rpy="0.00000000 0.00000000 0.00000000" xyz="0.000 0.230 0.000"/>
    <parent link="link_2"/>
    <child link="link_3"/>
    <axis xyz="0 0 1"/>
    <limit acceleration="17453.29251994" effort="32.21000000" jerk="17.45329252" lower="0" upper="2.7925268" velocity="1.57079633"/>
  </joint>
  <joint name="J4" type="revolute">
    <origin rpy="-1.57079633 0.00000000 0.00000000" xyz="0.050 0.000 0.000"/>
    <parent link="link_3"/>
    <child link="link_4"/>
    <axis xyz="0 0 1"/>
    <limit acceleration="17453.29251994" effort="32.21000000" jerk="17.45329252" lower="-3.4906585" upper="3.4906585" velocity="1.57079633"/>
  </joint>
  <joint name="J5" type="revolute">
    <origin rpy="1.57079633 0.00000000 0.00000000" xyz="0.000 0.000 0.270"/>
    <parent link="link_4"/>
    <child link="link_5"/>
    <axis xyz="0 0 1"/>
    <limit acceleration="17453.29251994" effort="32.21000000" jerk="17.45329252" lower="-2.0943951" upper="2.0943951" velocity="1.57079633"/>
  </joint>
  <joint name="J6" type="revolute">
    <origin rpy="-1.57079633 0.00000000 0.00000000" xyz="0.000 0.000 0.000"/>
    <parent link="link_5"/>
    <child link="link_6"/>
    <axis xyz="0 0 1"/>
    <limit acceleration="17453.29251994" effort="32.21000000" jerk="17.45329252" lower="-6.28318531" upper="6.28318531" velocity="1.57079633"/>
  </joint>
  <joint name="J6-tool0" type="fixed">
    <origin rpy="0 0 0" xyz="0 0 0"/>
    <parent link="link_6"/>
    <child link="tool0"/>
  </joint>
</robot>
